Traceback (most recent call last):
  File "/raid/infolab/ashwinr/RoPE/unlimiformer/src/data1_large/run_generation_standard.py", line 590, in <module>
    main()
  File "/raid/infolab/ashwinr/RoPE/unlimiformer/src/data1_large/run_generation_standard.py", line 429, in main
    raise ValueError(f"Unknown arguments detected: {set(unknown_args) & set(unknown_unlimiformer_args)}")
ValueError: Unknown arguments detected: {'5'}
