Traceback (most recent call last):
  File "/raid/infolab/ashwinr/RoPE/unlimiformer/src/run_generation.py", line 584, in <module>
    main()
  File "/raid/infolab/ashwinr/RoPE/unlimiformer/src/run_generation.py", line 426, in main
    raise ValueError(f"Unknown arguments detected: {set(unknown_args) & set(unknown_unlimiformer_args)}")
ValueError: Unknown arguments detected: {'0'}
